<sdf version='1.10'>
  <world name='diff_drive'>
    <physics name='1ms' type='ignored'>
      <max_step_size>0.001</max_step_size>
      <real_time_factor>1</real_time_factor>
      <real_time_update_rate>1000</real_time_update_rate>
    </physics>
    <plugin name='gz::sim::systems::Physics' filename='gz-sim-physics-system'/>
    <plugin name='gz::sim::systems::UserCommands' filename='gz-sim-user-commands-system'/>
    <plugin name='gz::sim::systems::SceneBroadcaster' filename='gz-sim-scene-broadcaster-system'/>
    <gravity>0 0 -9.8000000000000007</gravity>
    <magnetic_field>5.5644999999999998e-06 2.2875799999999999e-05 -4.2388400000000002e-05</magnetic_field>
    <atmosphere type='adiabatic'/>
    <scene>
      <ambient>0.400000006 0.400000006 0.400000006 1</ambient>
      <background>0.699999988 0.699999988 0.699999988 1</background>
      <shadows>true</shadows>
    </scene>
    <model name='ground_plane'>
      <static>true</static>
      <link name='link'>
        <collision name='collision'>
          <geometry>
            <plane>
              <normal>0 0 1</normal>
              <size>100 100</size>
            </plane>
          </geometry>
          <surface>
            <friction>
              <ode/>
            </friction>
            <bounce/>
            <contact/>
          </surface>
        </collision>
        <visual name='visual'>
          <geometry>
            <plane>
              <normal>0 0 1</normal>
              <size>100 100</size>
            </plane>
          </geometry>
          <material>
            <ambient>0.800000012 0.800000012 0.800000012 1</ambient>
            <diffuse>0.800000012 0.800000012 0.800000012 1</diffuse>
            <specular>0.800000012 0.800000012 0.800000012 1</specular>
          </material>
        </visual>
        <pose>0 0 0 0 0 0</pose>
        <inertial>
          <pose>0 0 0 0 0 0</pose>
          <mass>1</mass>
          <inertia>
            <ixx>1</ixx>
            <ixy>0</ixy>
            <ixz>0</ixz>
            <iyy>1</iyy>
            <iyz>0</iyz>
            <izz>1</izz>
          </inertia>
        </inertial>
        <enable_wind>false</enable_wind>
      </link>
      <pose>0 0 0 0 0 0</pose>
      <self_collide>false</self_collide>
    </model>
    <model name='vehicle_blue'>
      <pose>-3.5534353204358382e-07 2.0000000000003921 0.32499938652317373 -8.7532269763164841e-13 -1.0933334433716686e-06 -7.5542123009919984e-19</pose>
      <link name='chassis'>
        <pose>-0.15142700000000001 0 0.17499999999999999 0 0 0</pose>
        <inertial>
          <mass>1.14395</mass>
          <inertia>
            <ixx>0.126164</ixx>
            <ixy>0</ixy>
            <ixz>0</ixz>
            <iyy>0.41651899999999997</iyy>
            <iyz>0</iyz>
            <izz>0.481014</izz>
          </inertia>
          <pose>0 0 0 0 0 0</pose>
        </inertial>
        <visual name='visual'>
          <geometry>
            <box>
              <size>2.0114200000000002 1 0.56872599999999995</size>
            </box>
          </geometry>
          <material>
            <ambient>0.5 0.5 1 1</ambient>
            <diffuse>0.5 0.5 1 1</diffuse>
            <specular>0 0 1 1</specular>
          </material>
        </visual>
        <collision name='collision'>
          <geometry>
            <box>
              <size>2.0114200000000002 1 0.56872599999999995</size>
            </box>
          </geometry>
          <surface>
            <friction>
              <ode/>
            </friction>
            <bounce/>
            <contact/>
          </surface>
        </collision>
        <enable_wind>false</enable_wind>
      </link>
      <link name='left_wheel'>
        <pose>0.55428299999999986 0.62502900000000006 -0.025000000000000078 -1.5706999999999995 -4.5917136958347845e-17 -4.4983243231618341e-21</pose>
        <inertial>
          <mass>2</mass>
          <inertia>
            <ixx>0.14583299999999999</ixx>
            <ixy>0</ixy>
            <ixz>0</ixz>
            <iyy>0.14583299999999999</iyy>
            <iyz>0</iyz>
            <izz>0.125</izz>
          </inertia>
          <pose>0 0 0 0 0 0</pose>
        </inertial>
        <visual name='visual'>
          <geometry>
            <sphere>
              <radius>0.29999999999999999</radius>
            </sphere>
          </geometry>
          <material>
            <ambient>0.200000003 0.200000003 0.200000003 1</ambient>
            <diffuse>0.200000003 0.200000003 0.200000003 1</diffuse>
            <specular>0.200000003 0.200000003 0.200000003 1</specular>
          </material>
        </visual>
        <collision name='collision'>
          <geometry>
            <sphere>
              <radius>0.29999999999999999</radius>
            </sphere>
          </geometry>
          <surface>
            <friction>
              <ode>
                <mu>1</mu>
                <mu2>1</mu2>
                <slip1>0.035000000000000003</slip1>
                <slip2>0</slip2>
                <fdir1>0 0 1</fdir1>
              </ode>
              <bullet>
                <friction>1</friction>
                <friction2>1</friction2>
                <rolling_friction>0.10000000000000001</rolling_friction>
                <spinning_friction>0.1</spinning_friction>
              </bullet>
            </friction>
            <bounce/>
            <contact/>
          </surface>
        </collision>
        <enable_wind>false</enable_wind>
      </link>
      <link name='right_wheel'>
        <pose>0.55428199999999994 -0.62502899999999939 -0.025000000000000078 -1.5706999999999995 -4.5943789910286623e-17 -4.4996080198913545e-21</pose>
        <inertial>
          <mass>2</mass>
          <inertia>
            <ixx>0.14583299999999999</ixx>
            <ixy>0</ixy>
            <ixz>0</ixz>
            <iyy>0.14583299999999999</iyy>
            <iyz>0</iyz>
            <izz>0.125</izz>
          </inertia>
          <pose>0 0 0 0 0 0</pose>
        </inertial>
        <visual name='visual'>
          <geometry>
            <sphere>
              <radius>0.29999999999999999</radius>
            </sphere>
          </geometry>
          <material>
            <ambient>0.200000003 0.200000003 0.200000003 1</ambient>
            <diffuse>0.200000003 0.200000003 0.200000003 1</diffuse>
            <specular>0.200000003 0.200000003 0.200000003 1</specular>
          </material>
        </visual>
        <collision name='collision'>
          <geometry>
            <sphere>
              <radius>0.29999999999999999</radius>
            </sphere>
          </geometry>
          <surface>
            <friction>
              <ode>
                <mu>1</mu>
                <mu2>1</mu2>
                <slip1>0.035000000000000003</slip1>
                <slip2>0</slip2>
                <fdir1>0 0 1</fdir1>
              </ode>
              <bullet>
                <friction>1</friction>
                <friction2>1</friction2>
                <rolling_friction>0.10000000000000001</rolling_friction>
                <spinning_friction>0.1</spinning_friction>
              </bullet>
            </friction>
            <bounce/>
            <contact/>
          </surface>
        </collision>
        <enable_wind>false</enable_wind>
      </link>
      <link name='caster'>
        <pose>-0.95713790224647233 1.2878587085651816e-14 -0.1249992621046398 -3.1515729198389178e-12 5.8903080736177938e-06 -1.4379561714120133e-18</pose>
        <inertial>
          <mass>1</mass>
          <inertia>
            <ixx>0.10000000000000001</ixx>
            <ixy>0</ixy>
            <ixz>0</ixz>
            <iyy>0.10000000000000001</iyy>
            <iyz>0</iyz>
            <izz>0.10000000000000001</izz>
          </inertia>
          <pose>0 0 0 0 0 0</pose>
        </inertial>
        <visual name='visual'>
          <geometry>
            <sphere>
              <radius>0.20000000000000001</radius>
            </sphere>
          </geometry>
          <material>
            <ambient>0.200000003 0.200000003 0.200000003 1</ambient>
            <diffuse>0.200000003 0.200000003 0.200000003 1</diffuse>
            <specular>0.200000003 0.200000003 0.200000003 1</specular>
          </material>
        </visual>
        <collision name='collision'>
          <geometry>
            <sphere>
              <radius>0.20000000000000001</radius>
            </sphere>
          </geometry>
          <surface>
            <friction>
              <ode/>
            </friction>
            <bounce/>
            <contact/>
          </surface>
        </collision>
        <enable_wind>false</enable_wind>
      </link>
      <joint name='left_wheel_joint' type='revolute'>
        <parent>chassis</parent>
        <child>left_wheel</child>
        <axis>
          <xyz>0 0 1</xyz>
          <limit>
            <lower>-1.7976900000000001e+308</lower>
            <upper>1.7976900000000001e+308</upper>
            <effort>inf</effort>
            <velocity>inf</velocity>
            <stiffness>100000000</stiffness>
            <dissipation>1</dissipation>
          </limit>
          <dynamics>
            <spring_reference>0</spring_reference>
            <spring_stiffness>0</spring_stiffness>
            <damping>0</damping>
            <friction>0</friction>
          </dynamics>
        </axis>
        <pose>0 0 1.1102230246251565e-16 0 0 0</pose>
      </joint>
      <joint name='right_wheel_joint' type='revolute'>
        <parent>chassis</parent>
        <child>right_wheel</child>
        <axis>
          <xyz>0 0 1</xyz>
          <limit>
            <lower>-1.7976900000000001e+308</lower>
            <upper>1.7976900000000001e+308</upper>
            <effort>inf</effort>
            <velocity>inf</velocity>
            <stiffness>100000000</stiffness>
            <dissipation>1</dissipation>
          </limit>
          <dynamics>
            <spring_reference>0</spring_reference>
            <spring_stiffness>0</spring_stiffness>
            <damping>0</damping>
            <friction>0</friction>
          </dynamics>
        </axis>
        <pose>-1.1102230246251565e-16 0 0 0 0 0</pose>
      </joint>
      <joint name='caster_wheel' type='ball'>
        <parent>chassis</parent>
        <child>caster</child>
        <pose>0 0 0 0 0 0</pose>
      </joint>
      <plugin name='gz::sim::systems::DiffDrive' filename='gz-sim-diff-drive-system'>
        <left_joint>left_wheel_joint</left_joint>
        <right_joint>right_wheel_joint</right_joint>
        <wheel_separation>1.25</wheel_separation>
        <wheel_radius>0.3</wheel_radius>
        <odom_publish_frequency>1</odom_publish_frequency>
        <max_linear_acceleration>1</max_linear_acceleration>
        <min_linear_acceleration>-1</min_linear_acceleration>
        <max_angular_acceleration>2</max_angular_acceleration>
        <min_angular_acceleration>-2</min_angular_acceleration>
        <max_linear_velocity>0.5</max_linear_velocity>
        <min_linear_velocity>-0.5</min_linear_velocity>
        <max_angular_velocity>1</max_angular_velocity>
        <min_angular_velocity>-1</min_angular_velocity>
      </plugin>
      <static>false</static>
      <self_collide>false</self_collide>
    </model>
    <model name='vehicle_green'>
      <pose>-3.5534353204358382e-07 -1.9999999999996028 0.32499938652317373 -8.7532266116650304e-13 -1.0933334433716442e-06 -7.5609745047090164e-19</pose>
      <link name='chassis'>
        <pose>-0.15142700000000001 0 0.17499999999999999 0 0 0</pose>
        <inertial>
          <mass>1.14395</mass>
          <inertia>
            <ixx>0.126164</ixx>
            <ixy>0</ixy>
            <ixz>0</ixz>
            <iyy>0.41651899999999997</iyy>
            <iyz>0</iyz>
            <izz>0.481014</izz>
          </inertia>
          <pose>0 0 0 0 0 0</pose>
        </inertial>
        <visual name='visual'>
          <geometry>
            <box>
              <size>2.0114200000000002 1 0.56872599999999995</size>
            </box>
          </geometry>
          <material>
            <ambient>0.5 1 0.5 1</ambient>
            <diffuse>0.5 1 0.5 1</diffuse>
            <specular>0 1 0 1</specular>
          </material>
        </visual>
        <collision name='collision'>
          <geometry>
            <box>
              <size>2.0114200000000002 1 0.56872599999999995</size>
            </box>
          </geometry>
          <surface>
            <friction>
              <ode/>
            </friction>
            <bounce/>
            <contact/>
          </surface>
        </collision>
        <enable_wind>false</enable_wind>
      </link>
      <link name='left_wheel'>
        <pose>0.55428299999999986 0.62502899999999983 -0.025000000000000078 -1.5706999999999995 -4.5954870322133154e-17 -4.4228839943423966e-21</pose>
        <inertial>
          <mass>2</mass>
          <inertia>
            <ixx>0.14583299999999999</ixx>
            <ixy>0</ixy>
            <ixz>0</ixz>
            <iyy>0.14583299999999999</iyy>
            <iyz>0</iyz>
            <izz>0.125</izz>
          </inertia>
          <pose>0 0 0 0 0 0</pose>
        </inertial>
        <visual name='visual'>
          <geometry>
            <sphere>
              <radius>0.29999999999999999</radius>
            </sphere>
          </geometry>
          <material>
            <ambient>0.200000003 0.200000003 0.200000003 1</ambient>
            <diffuse>0.200000003 0.200000003 0.200000003 1</diffuse>
            <specular>0.200000003 0.200000003 0.200000003 1</specular>
          </material>
        </visual>
        <collision name='collision'>
          <geometry>
            <sphere>
              <radius>0.29999999999999999</radius>
            </sphere>
          </geometry>
          <surface>
            <friction>
              <ode>
                <mu>1</mu>
                <mu2>1</mu2>
                <slip1>0.035000000000000003</slip1>
                <slip2>0</slip2>
                <fdir1>0 0 1</fdir1>
              </ode>
              <bullet>
                <friction>1</friction>
                <friction2>1</friction2>
                <rolling_friction>0.10000000000000001</rolling_friction>
                <spinning_friction>0.1</spinning_friction>
              </bullet>
            </friction>
            <bounce/>
            <contact/>
          </surface>
        </collision>
        <enable_wind>false</enable_wind>
      </link>
      <link name='right_wheel'>
        <pose>0.55428199999999994 -0.6250290000000005 -0.025000000000000078 -1.5706999999999995 -4.5985341530434804e-17 -4.4992194339520349e-21</pose>
        <inertial>
          <mass>2</mass>
          <inertia>
            <ixx>0.14583299999999999</ixx>
            <ixy>0</ixy>
            <ixz>0</ixz>
            <iyy>0.14583299999999999</iyy>
            <iyz>0</iyz>
            <izz>0.125</izz>
          </inertia>
          <pose>0 0 0 0 0 0</pose>
        </inertial>
        <visual name='visual'>
          <geometry>
            <sphere>
              <radius>0.29999999999999999</radius>
            </sphere>
          </geometry>
          <material>
            <ambient>0.200000003 0.200000003 0.200000003 1</ambient>
            <diffuse>0.200000003 0.200000003 0.200000003 1</diffuse>
            <specular>0.200000003 0.200000003 0.200000003 1</specular>
          </material>
        </visual>
        <collision name='collision'>
          <geometry>
            <sphere>
              <radius>0.29999999999999999</radius>
            </sphere>
          </geometry>
          <surface>
            <friction>
              <ode>
                <mu>1</mu>
                <mu2>1</mu2>
                <slip1>0.035000000000000003</slip1>
                <slip2>0</slip2>
                <fdir1>0 0 1</fdir1>
              </ode>
              <bullet>
                <friction>1</friction>
                <friction2>1</friction2>
                <rolling_friction>0.10000000000000001</rolling_friction>
                <spinning_friction>0.1</spinning_friction>
              </bullet>
            </friction>
            <bounce/>
            <contact/>
          </surface>
        </collision>
        <enable_wind>false</enable_wind>
      </link>
      <link name='caster'>
        <pose>-0.95713790224647233 7.1054273576010019e-15 -0.1249992621046398 -3.1515695061907738e-12 5.8903080736177573e-06 -1.4377452488366366e-18</pose>
        <inertial>
          <mass>1</mass>
          <inertia>
            <ixx>0.10000000000000001</ixx>
            <ixy>0</ixy>
            <ixz>0</ixz>
            <iyy>0.10000000000000001</iyy>
            <iyz>0</iyz>
            <izz>0.10000000000000001</izz>
          </inertia>
          <pose>0 0 0 0 0 0</pose>
        </inertial>
        <visual name='visual'>
          <geometry>
            <sphere>
              <radius>0.20000000000000001</radius>
            </sphere>
          </geometry>
          <material>
            <ambient>0.200000003 0.200000003 0.200000003 1</ambient>
            <diffuse>0.200000003 0.200000003 0.200000003 1</diffuse>
            <specular>0.200000003 0.200000003 0.200000003 1</specular>
          </material>
        </visual>
        <collision name='collision'>
          <geometry>
            <sphere>
              <radius>0.20000000000000001</radius>
            </sphere>
          </geometry>
          <surface>
            <friction>
              <ode/>
            </friction>
            <bounce/>
            <contact/>
          </surface>
        </collision>
        <enable_wind>false</enable_wind>
      </link>
      <joint name='left_wheel_joint' type='revolute'>
        <parent>chassis</parent>
        <child>left_wheel</child>
        <axis>
          <xyz>0 0 1</xyz>
          <limit>
            <lower>-1.7976900000000001e+308</lower>
            <upper>1.7976900000000001e+308</upper>
            <effort>inf</effort>
            <velocity>inf</velocity>
            <stiffness>100000000</stiffness>
            <dissipation>1</dissipation>
          </limit>
          <dynamics>
            <spring_reference>0</spring_reference>
            <spring_stiffness>0</spring_stiffness>
            <damping>0</damping>
            <friction>0</friction>
          </dynamics>
        </axis>
        <pose>0 0 1.1102230246251565e-16 0 0 0</pose>
      </joint>
      <joint name='right_wheel_joint' type='revolute'>
        <parent>chassis</parent>
        <child>right_wheel</child>
        <axis>
          <xyz>0 0 1</xyz>
          <limit>
            <lower>-1.7976900000000001e+308</lower>
            <upper>1.7976900000000001e+308</upper>
            <effort>inf</effort>
            <velocity>inf</velocity>
            <stiffness>100000000</stiffness>
            <dissipation>1</dissipation>
          </limit>
          <dynamics>
            <spring_reference>0</spring_reference>
            <spring_stiffness>0</spring_stiffness>
            <damping>0</damping>
            <friction>0</friction>
          </dynamics>
        </axis>
        <pose>-1.1102230246251565e-16 0 0 0 0 0</pose>
      </joint>
      <joint name='caster_wheel' type='ball'>
        <parent>chassis</parent>
        <child>caster</child>
        <pose>0 0 0 0 0 0</pose>
      </joint>
      <plugin name='gz::sim::systems::DiffDrive' filename='gz-sim-diff-drive-system'>
        <left_joint>left_wheel_joint</left_joint>
        <right_joint>right_wheel_joint</right_joint>
        <wheel_separation>1.25</wheel_separation>
        <wheel_radius>0.3</wheel_radius>
        <max_linear_acceleration>1</max_linear_acceleration>
        <min_linear_acceleration>-1</min_linear_acceleration>
        <max_angular_acceleration>2</max_angular_acceleration>
        <min_angular_acceleration>-2</min_angular_acceleration>
        <max_linear_velocity>0.5</max_linear_velocity>
        <min_linear_velocity>-0.5</min_linear_velocity>
        <max_angular_velocity>1</max_angular_velocity>
        <min_angular_velocity>-1</min_angular_velocity>
      </plugin>
      <static>false</static>
      <self_collide>false</self_collide>
    </model>
    <light name='sun' type='directional'>
      <pose>0 0 10 0 0 0</pose>
      <cast_shadows>true</cast_shadows>
      <intensity>1</intensity>
      <direction>-0.5 0.10000000000000001 -0.90000000000000002</direction>
      <diffuse>1 1 1 1</diffuse>
      <specular>0.5 0.5 0.5 1</specular>
      <attenuation>
        <range>1000</range>
        <linear>0.01</linear>
        <constant>0.90000000000000002</constant>
        <quadratic>0.001</quadratic>
      </attenuation>
      <spot>
        <inner_angle>0</inner_angle>
        <outer_angle>0</outer_angle>
        <falloff>0</falloff>
      </spot>
    </light>
  </world>
</sdf>
