<?xml version='1.0'?>
<sdf version='1.6'>
  <model name='gimbal_edit_2d'>
    <pose>0 0 0.18 0 0 0</pose>
    <link name='base_link'>
      <inertial>
        <mass>0.2</mass>
        <inertia>
          <ixx>0.0001</ixx>
          <ixy>0</ixy>
          <ixz>0</ixz>
          <iyy>0.0001</iyy>
          <iyz>0</iyz>
          <izz>0.0001</izz>
        </inertia>
      </inertial>
      <visual name='base_main_viz'>
        <geometry>
          <mesh>
            <scale>0.001 0.001 0.001</scale>
            <uri>model://gimbal_edit_2d/meshes/base_main.dae</uri>
          </mesh>
        </geometry>
        <material>
          <ambient>0.1 0.1 0.1</ambient>
          <diffuse>0.1 0.1 0.1</diffuse>
          <specular>0.01 0.01 0.01 1.0</specular>
        </material>
      </visual>
      <collision name='base_col'>
        <pose>0.01 0.075 -0.025 0 0 0</pose>
        <geometry>
          <box>
            <size>0.1 0.05 0.15</size>
          </box>
        </geometry>
      </collision>
    </link>
    <link name='roll_link'>
      <inertial>
        <mass>0.01</mass>
        <inertia>
          <ixx>0.00001</ixx>
          <ixy>0</ixy>
          <ixz>0</ixz>
          <iyy>0.00001</iyy>
          <iyz>0</iyz>
          <izz>0.00001</izz>
        </inertia>
      </inertial>
      <visual name='roll_viz'>
        <geometry>
          <mesh>
            <scale>0.001 0.001 0.001</scale>
            <uri>model://gimbal_edit_2d/meshes/base_arm.dae</uri>
          </mesh>
        </geometry>
        <material>
          <ambient>0.1 0.1 0.1</ambient>
          <diffuse>0.1 0.1 0.1</diffuse>
          <specular>0.01 0.01 0.01 1.0</specular>
        </material>
      </visual>
      <collision name='roll_col'>
        <geometry>
          <mesh>
            <scale>0.001 0.001 0.001</scale>
            <uri>model://gimbal_edit_2d/meshes/base_arm.dae</uri>
          </mesh>
        </geometry>
      </collision>
    </link>
    <joint name='roll_joint' type='revolute'>
      <parent>base_link</parent>
      <child>roll_link</child>
      <axis>
        <xyz>0 0 1</xyz>
        <dynamics>
          <damping>0.5</damping>
        </dynamics>
        <limit>
          <lower>-1.57079632</lower>
          <upper>1.57079632</upper>
        </limit>
      </axis>
      <pose>0.01 0 -0.04 0 0 0</pose>
    </joint>


    <include>
      <uri>model://rgbd_cam</uri>
    </include>
    <joint name='tilt_joint' type='revolute'>
      <parent>roll_link</parent>
      <child>rgbd_cam::base_link</child>
      <axis>
        <xyz>1 0 0</xyz>
        <dynamics>
          <damping>0.5</damping>
        </dynamics>
        <limit>
          <lower>-1.57079632</lower>
          <upper>1.57079632</upper>
        </limit>
      </axis>
      <pose>0 0 0.02 0 0 0</pose>
    </joint>

  </model>
</sdf>
